Workbook
Name allQAs: Variables!$C$2:$C$131
Name qaStatus: Variables!$G$2:$G$1048576
Name process: Variables!$M$2:$M$1048576
Name env: Variables!$I$2:$I$1048576
Name atTesters: Variables!$E$2:$E$1048576
Name allTesters: Variables!$A$2:$A$134
Name pageStatus: Variables!$K$2:$K$1048576
Name envStatus: Variables!$Y$2:$Y$13
Name projectStatus: Variables!$O$2:$O$1048576
Name userImpact: Variables!$U$2:$U$1048576
Name devStatus: Variables!$S$2:$S$1048576
Name testerStatus: Variables!$Q$2:$Q$1048576

Sheet Overview
E2: Audit Performed For | F2: Example name | J2: Operating system | K2: Browser | L2: Assistive technologies | M2: Automated tools | O2: *Important note
E3: Audit Type | F3: Website/Mobile App | J3: Windows 11 | K3: Chrome | L3: JAWS 2024 | M3: Wave, ARC toolkit, CCA | O3: ="1. The web asset has been audited in its present condition and Quality Assured by IAAP certified auditor. As per our offer and initial scope, the comprehensive report covers issues / bugs that have been found during the audit as on " & TEXT(TODAY(),"mmmm d, yyyy") & "." -> 1. The web asset has been audited in its present condition and Quality Assured by IAAP certified auditor. As per our offer and initial scope, the comprehensive report covers issues / bugs that have been found during the audit as on March 18, 2026.
E4: Audit Performed By | F4: Sakshi Infotech Solutions LLP | J4: Windows 11 | K4: Firefox | L4: NVDA | M4: Wave, ARC toolkit, CCA
E5: IAAP-Certified Auditor | F5: Sangam Nishad | J5: Windows 11 | K5: Chrome | L5: ZoomText and Dragon NaturalSpeaking | M5: N/A
E6: Audit Date | F6: =TODAY() -> 46099 | J6: MacOS | K6: Safari | L6: VoiceOver | M6: Wave, ARC toolkit, CCA | O6: 2. Till such time that the VPAT (Voluntary Product Accessibility Template) of this asset is not released, there should be no changes made to the asset in the form of enhancements and modifications to its underlying codebase, system configuration, infrastructure, accessibility settings, or any associated documentation. Changes if any carried out within this asset will tantamount to re-scope and re-work on the asset. Changes to the web asset will effect the Accessibility Conformance Report (ACR) are without risk and responsibility of the IAAP audit report.
J7: Android OS | K7: Chrome | L7: TalkBack | M7: Accessbility Scanner
J8: Iphone OS | K8: Safari | L8: VoiceOver | M8: Accessbility Checker
E10: WCAG 2.2 Conformance | F10: Level A | G10: Level AA | H10: Total | J10: Top 5 Issues
E11: Passed/NA | F11: =F13-F12 -> 32 | G11: =G13-G12 -> 24 | H11: =SUM(F11:G11) -> 56 | J11: Sr. no. | K11: Issues Name | M11: Success Criteria
E12: Failed | F12: =COUNTIFS('Conformance Score'!C:C, "A", 'Conformance Score'!E:E, ">0") -> 0 | G12: =COUNTIFS('Conformance Score'!C:C, "AA", 'Conformance Score'!E:E, ">0") -> 0 | H12: =SUM(F12:G12) -> 0 | J12: 1 | K12: =IFERROR(__xludf.DUMMYFUNCTION("ARRAY_CONSTRAIN( ARRAYFORMULA( LET( data, FILTER( { 'Final Report'!D2:D1000, 'Final Report'!N2:N1000, 'Final Report'!L2:L1000, 'Final Report'!P2:P1000 }, 'Fi"&"nal Report'!L2:L1000<>"""", 'Final Report'!P2:P1000<>"""" ), sorted, SORT( data, 4, TRUE, 3, TRUE ), uniqueSC, UNIQUE(INDEX(sorted,,2)), thisSC, IFERROR(I"&"NDEX(uniqueSC,1),""""), pos, IF(thisSC="""","""", MATCH(thisSC, INDEX(sorted,,2), 0)), IF( thisSC="""", """", INDEX(sorted, pos, 1) ) ) ), 1, 1 ) "),"") | M12: =IFERROR(__xludf.DUMMYFUNCTION("ARRAY_CONSTRAIN( ARRAYFORMULA( LET( data, FILTER( { 'Final Report'!D2:D1000, 'Final Report'!N2:N1000, 'Final Report'!L2:L1000, 'Final Report'!P2:P1000 }, 'Fi"&"nal Report'!L2:L1000<>"""", 'Final Report'!P2:P1000<>"""" ), sorted, SORT( data, 4, TRUE, 3, TRUE ), uniqueSC, UNIQUE(INDEX(sorted,,2)), IFERROR(INDEX(uniqueSC, 1), "&""""") ) ), 1, 1 ) "),"")
E13: Total | F13: 32 | G13: 24 | H13: =SUM(H11:H12) -> 56 | J13: 2 | K13: =IFERROR(__xludf.DUMMYFUNCTION("ARRAY_CONSTRAIN( ARRAYFORMULA( LET( data, FILTER( { 'Final Report'!D2:D1000, 'Final Report'!N2:N1000, 'Final Report'!L2:L1000, 'Final Report'!P2:P1000 }, 'Fi"&"nal Report'!L2:L1000<>"""", 'Final Report'!P2:P1000<>"""" ), sorted, SORT( data, 4, TRUE, 3, TRUE ), uniqueSC, UNIQUE(INDEX(sorted,,2)), thisSC, IFERROR(I"&"NDEX(uniqueSC, 2), """"), pos, IF(thisSC="""", """", MATCH(thisSC, INDEX(sorted,,2), 0)), IF( thisSC="""", """", INDEX(sorted, pos, 1) ) ) ), 1, 1 ) "),"") | M13: =IFERROR(__xludf.DUMMYFUNCTION("ARRAY_CONSTRAIN( ARRAYFORMULA( LET( data, FILTER( { 'Final Report'!D2:D1000, 'Final Report'!N2:N1000, 'Final Report'!L2:L1000, 'Final Report'!P2:P1000 }, 'Fi"&"nal Report'!L2:L1000<>"""", 'Final Report'!P2:P1000<>"""" ), sorted, SORT( data, 4, TRUE, 3, TRUE ), uniqueSC, UNIQUE(INDEX(sorted,,2)), IFERROR(INDEX(uniqueSC, 2), "&""""") ) ), 1, 1 ) "),"") | O13: 3. Incase there is a requirement to make modifications to asset being tested, separate request needs to addressed via email. After scoping and agreement in pricing, the additional pages will be tested and included in the overall VPAT report.
J14: 3 | K14: =IFERROR(__xludf.DUMMYFUNCTION("ARRAY_CONSTRAIN( ARRAYFORMULA( LET( data, FILTER( { 'Final Report'!D2:D1000, 'Final Report'!N2:N1000, 'Final Report'!L2:L1000, 'Final Report'!P2:P1000 }, 'Fi"&"nal Report'!L2:L1000<>"""", 'Final Report'!P2:P1000<>"""" ), sorted, SORT( data, 4, TRUE, 3, TRUE ), uniqueSC, UNIQUE(INDEX(sorted,,2)), thisSC, IFERROR(INDE"&"X(uniqueSC, 3), """"), pos, IF(thisSC="""", """", MATCH(thisSC, INDEX(sorted,,2), 0)), IF( thisSC="""", """", INDEX(sorted, pos, 1) ) ) ), 1, 1 ) "),"") | M14: =IFERROR(__xludf.DUMMYFUNCTION("ARRAY_CONSTRAIN( ARRAYFORMULA( LET( data, FILTER( { 'Final Report'!D2:D1000, 'Final Report'!N2:N1000, 'Final Report'!L2:L1000, 'Final Report'!P2:P1000 }, 'Fi"&"nal Report'!L2:L1000<>"""", 'Final Report'!P2:P1000<>"""" ), sorted, SORT( data, 4, TRUE, 3, TRUE ), uniqueSC, UNIQUE(INDEX(sorted,,2)), IFERROR(INDEX(uniqueSC, 3), "&""""") ) ), 1, 1 ) "),"")
B15: =IFERROR(__xludf.DUMMYFUNCTION("{ ""Users Affected"",""Issue counts""; IFERROR( QUERY( FILTER( TRIM(FLATTEN(SPLIT( TEXTJOIN(""|"", TRUE, ARRAYFORMULA( IF('Final Report'!M2:M1000<>"""", REGEXREPLACE('Final Report"&"'!M2:M1000, "",\s*"", ""|""), """" ) ) ), ""|"" ))), TRIM(FLATTEN(SPLIT( TEXTJOIN(""|"", TRUE, ARRAYFORMULA( IF('Final Report'!M2:M1000<>"""&""", REGEXREPLACE('Final Report'!M2:M1000, "",\s*"", ""|""), """" ) ) ), ""|"" ))) <> """" ), ""select Col1, count(Col1) group by Col1 order b"&"y count(Col1) desc label Col1 '', count(Col1) ''"", 0 ), {""No disabilities affected"",0} ) }"),"Users Affected") -> Users Affected | C15: =IFERROR(__xludf.DUMMYFUNCTION("""COMPUTED_VALUE"""),"Issue counts") -> Issue counts | J15: 4 | K15: =IFERROR(__xludf.DUMMYFUNCTION("ARRAY_CONSTRAIN( ARRAYFORMULA( LET( data, FILTER( { 'Final Report'!D2:D1000, 'Final Report'!N2:N1000, 'Final Report'!L2:L1000, 'Final Report'!P2:P1000 }, 'Fi"&"nal Report'!L2:L1000<>"""", 'Final Report'!P2:P1000<>"""" ), sorted, SORT( data, 4, TRUE, 3, TRUE ), uniqueSC, UNIQUE(INDEX(sorted,,2)), thisSC, IFERROR(INDE"&"X(uniqueSC, 4), """"), pos, IF(thisSC="""", """", MATCH(thisSC, INDEX(sorted,,2), 0)), IF( thisSC="""", """", INDEX(sorted, pos, 1) ) ) ), 1, 1 ) "),"") | M15: =IFERROR(__xludf.DUMMYFUNCTION("ARRAY_CONSTRAIN( ARRAYFORMULA( LET( data, FILTER( { 'Final Report'!D2:D1000, 'Final Report'!N2:N1000, 'Final Report'!L2:L1000, 'Final Report'!P2:P1000 }, 'Fi"&"nal Report'!L2:L1000<>"""", 'Final Report'!P2:P1000<>"""" ), sorted, SORT( data, 4, TRUE, 3, TRUE ), uniqueSC, UNIQUE(INDEX(sorted,,2)), IFERROR(INDEX(uniqueSC, 4), "&""""") ) ), 1, 1 ) "),"")
B16: =IFERROR(__xludf.DUMMYFUNCTION("""COMPUTED_VALUE"""),"No disabilities affected") -> No disabilities affected | C16: =IFERROR(__xludf.DUMMYFUNCTION("""COMPUTED_VALUE"""),0.0) -> 0 | J16: 5 | K16: =IFERROR(__xludf.DUMMYFUNCTION("ARRAY_CONSTRAIN( ARRAYFORMULA( LET( data, FILTER( { 'Final Report'!D2:D1000, 'Final Report'!N2:N1000, 'Final Report'!L2:L1000, 'Final Report'!P2:P1000 }, 'Fi"&"nal Report'!L2:L1000<>"""", 'Final Report'!P2:P1000<>"""" ), sorted, SORT( data, 4, TRUE, 3, TRUE ), uniqueSC, UNIQUE(INDEX(sorted,,2)), thisSC, IFERROR(INDE"&"X(uniqueSC, 5), """"), pos, IF(thisSC="""", """", MATCH(thisSC, INDEX(sorted,,2), 0)), IF( thisSC="""", """", INDEX(sorted, pos, 1) ) ) ), 1, 1 ) "),"") | M16: =IFERROR(__xludf.DUMMYFUNCTION("ARRAY_CONSTRAIN( ARRAYFORMULA( LET( data, FILTER( { 'Final Report'!D2:D1000, 'Final Report'!N2:N1000, 'Final Report'!L2:L1000, 'Final Report'!P2:P1000 }, 'Fi"&"nal Report'!L2:L1000<>"""", 'Final Report'!P2:P1000<>"""" ), sorted, SORT( data, 4, TRUE, 3, TRUE ), uniqueSC, UNIQUE(INDEX(sorted,,2)), IFERROR(INDEX(uniqueSC, 5), "&""""") ) ), 1, 1 ) "),"") | O16: 4. For the purpose of remediation, the Implementation Officer/Engineer/Developer is required to adhere to all recommendations provided by our certified experts to ensure compliance.
O19: ="5. The VPAT/ACR report will be issued based on the remediation of the initial assessment report dated " & TEXT(TODAY(),"mmmm d, yyyy") & "." -> 5. The VPAT/ACR report will be issued based on the remediation of the initial assessment report dated March 18, 2026.
O23: =IFERROR(__xludf.DUMMYFUNCTION("QUERY('Final Report'!L2:L1000, ""select L, count(L) where L is not null group by L label L 'Severity', count(L) 'Issue Count'"", 0) "),"Severity") -> Severity | P23: =IFERROR(__xludf.DUMMYFUNCTION("""COMPUTED_VALUE"""),"Issue Count") -> Issue Count
B28: Resource Name | C28: Resource Type
B29: Roshani Rathod | C29: Standard Tester
B30: Harshada Yadav | C30: Standard Tester
B31: Aditya Mankar | C31: Assistive Technology Tester
B32: Aarti Thombare | C32: Quality Assurance (QA)

Sheet URL Details
A1: Page No. | B1: Page Name | C1: Unique URLs | D1: Grouped URLs | E1: Rows | F1: AT Testers | G1: Tester names | H1: QA name | I1: Notes | J1: Status | K1: Environment
A2: G1 | B2: Global | C2: On All pages | D2: On All Pages | E2: 2-30
A3: P01 | D3: =IFERROR(__xludf.DUMMYFUNCTION("IF(A3="""","""", IFERROR(TEXTJOIN("", ""&CHAR(10), TRUE, FILTER('All URLs'!A2:A500, 'All URLs'!B2:B500=A3, 'All URLs'!A2:A500<>"""") ),"""") ) "),"") | E3: 31-60
A4: P02 | D4: =IFERROR(__xludf.DUMMYFUNCTION("IF(A4="""","""", IFERROR(TEXTJOIN("", ""&CHAR(10), TRUE, FILTER('All URLs'!A3:A501, 'All URLs'!B3:B501=A4, 'All URLs'!A3:A501<>"""") ),"""") ) "),"") | E4: 61-90
A5: P03 | D5: =IFERROR(__xludf.DUMMYFUNCTION("IF(A5="""","""", IFERROR(TEXTJOIN("", ""&CHAR(10), TRUE, FILTER('All URLs'!A4:A502, 'All URLs'!B4:B502=A5, 'All URLs'!A4:A502<>"""") ),"""") ) "),"") | E5: 91-120
A6: P04 | D6: =IFERROR(__xludf.DUMMYFUNCTION("IF(A6="""","""", IFERROR(TEXTJOIN("", ""&CHAR(10), TRUE, FILTER('All URLs'!A5:A503, 'All URLs'!B5:B503=A6, 'All URLs'!A5:A503<>"""") ),"""") ) "),"") | E6: 121-150
A7: P05 | D7: =IFERROR(__xludf.DUMMYFUNCTION("IF(A7="""","""", IFERROR(TEXTJOIN("", ""&CHAR(10), TRUE, FILTER('All URLs'!A6:A504, 'All URLs'!B6:B504=A7, 'All URLs'!A6:A504<>"""") ),"""") ) "),"") | E7: 151-180
A8: P06 | D8: =IFERROR(__xludf.DUMMYFUNCTION("IF(A8="""","""", IFERROR(TEXTJOIN("", ""&CHAR(10), TRUE, FILTER('All URLs'!A7:A505, 'All URLs'!B7:B505=A8, 'All URLs'!A7:A505<>"""") ),"""") ) "),"") | E8: 181-210
A9: P07 | D9: =IFERROR(__xludf.DUMMYFUNCTION("IF(A9="""","""", IFERROR(TEXTJOIN("", ""&CHAR(10), TRUE, FILTER('All URLs'!A8:A506, 'All URLs'!B8:B506=A9, 'All URLs'!A8:A506<>"""") ),"""") ) "),"") | E9: 211-240
A10: P08 | D10: =IFERROR(__xludf.DUMMYFUNCTION("IF(A10="""","""", IFERROR(TEXTJOIN("", ""&CHAR(10), TRUE, FILTER('All URLs'!A9:A507, 'All URLs'!B9:B507=A10, 'All URLs'!A9:A507<>"""") ),"""") ) "),"") | E10: 241-270
A11: P09 | D11: =IFERROR(__xludf.DUMMYFUNCTION("IF(A11="""","""", IFERROR(TEXTJOIN("", ""&CHAR(10), TRUE, FILTER('All URLs'!A10:A508, 'All URLs'!B10:B508=A11, 'All URLs'!A10:A508<>"""") ),"""") ) "),"") | E11: 271-300
A12: P10 | D12: =IFERROR(__xludf.DUMMYFUNCTION("IF(A12="""","""", IFERROR(TEXTJOIN("", ""&CHAR(10), TRUE, FILTER('All URLs'!A11:A509, 'All URLs'!B11:B509=A12, 'All URLs'!A11:A509<>"""") ),"""") ) "),"") | E12: 301-330
A13: P11 | D13: =IFERROR(__xludf.DUMMYFUNCTION("IF(A13="""","""", IFERROR(TEXTJOIN("", ""&CHAR(10), TRUE, FILTER('All URLs'!A12:A510, 'All URLs'!B12:B510=A13, 'All URLs'!A12:A510<>"""") ),"""") ) "),"") | E13: 331-360
A14: P12 | D14: =IFERROR(__xludf.DUMMYFUNCTION("IF(A14="""","""", IFERROR(TEXTJOIN("", ""&CHAR(10), TRUE, FILTER('All URLs'!A13:A511, 'All URLs'!B13:B511=A14, 'All URLs'!A13:A511<>"""") ),"""") ) "),"") | E14: 361-390
A15: P13 | D15: =IFERROR(__xludf.DUMMYFUNCTION("IF(A15="""","""", IFERROR(TEXTJOIN("", ""&CHAR(10), TRUE, FILTER('All URLs'!A14:A512, 'All URLs'!B14:B512=A15, 'All URLs'!A14:A512<>"""") ),"""") ) "),"") | E15: 391-420
A16: P14 | D16: =IFERROR(__xludf.DUMMYFUNCTION("IF(A16="""","""", IFERROR(TEXTJOIN("", ""&CHAR(10), TRUE, FILTER('All URLs'!A15:A513, 'All URLs'!B15:B513=A16, 'All URLs'!A15:A513<>"""") ),"""") ) "),"") | E16: 421-450
A17: P15 | D17: =IFERROR(__xludf.DUMMYFUNCTION("IF(A17="""","""", IFERROR(TEXTJOIN("", ""&CHAR(10), TRUE, FILTER('All URLs'!A16:A514, 'All URLs'!B16:B514=A17, 'All URLs'!A16:A514<>"""") ),"""") ) "),"") | E17: 451-480
A18: P16 | D18: =IFERROR(__xludf.DUMMYFUNCTION("IF(A18="""","""", IFERROR(TEXTJOIN("", ""&CHAR(10), TRUE, FILTER('All URLs'!A17:A515, 'All URLs'!B17:B515=A18, 'All URLs'!A17:A515<>"""") ),"""") ) "),"") | E18: 481-510
A19: P17 | D19: =IFERROR(__xludf.DUMMYFUNCTION("IF(A19="""","""", IFERROR(TEXTJOIN("", ""&CHAR(10), TRUE, FILTER('All URLs'!A18:A516, 'All URLs'!B18:B516=A19, 'All URLs'!A18:A516<>"""") ),"""") ) "),"") | E19: 511-540
A20: P18 | D20: =IFERROR(__xludf.DUMMYFUNCTION("IF(A20="""","""", IFERROR(TEXTJOIN("", ""&CHAR(10), TRUE, FILTER('All URLs'!A19:A517, 'All URLs'!B19:B517=A20, 'All URLs'!A19:A517<>"""") ),"""") ) "),"") | E20: 541-570
A21: P19 | D21: =IFERROR(__xludf.DUMMYFUNCTION("IF(A21="""","""", IFERROR(TEXTJOIN("", ""&CHAR(10), TRUE, FILTER('All URLs'!A20:A518, 'All URLs'!B20:B518=A21, 'All URLs'!A20:A518<>"""") ),"""") ) "),"") | E21: 571-600
A22: P20 | D22: =IFERROR(__xludf.DUMMYFUNCTION("IF(A22="""","""", IFERROR(TEXTJOIN("", ""&CHAR(10), TRUE, FILTER('All URLs'!A21:A519, 'All URLs'!B21:B519=A22, 'All URLs'!A21:A519<>"""") ),"""") ) "),"") | E22: 601-630
A23: P21 | D23: =IFERROR(__xludf.DUMMYFUNCTION("IF(A23="""","""", IFERROR(TEXTJOIN("", ""&CHAR(10), TRUE, FILTER('All URLs'!A22:A520, 'All URLs'!B22:B520=A23, 'All URLs'!A22:A520<>"""") ),"""") ) "),"") | E23: 631-660
A24: P22 | D24: =IFERROR(__xludf.DUMMYFUNCTION("IF(A24="""","""", IFERROR(TEXTJOIN("", ""&CHAR(10), TRUE, FILTER('All URLs'!A23:A521, 'All URLs'!B23:B521=A24, 'All URLs'!A23:A521<>"""") ),"""") ) "),"") | E24: 661-690
A25: P23 | D25: =IFERROR(__xludf.DUMMYFUNCTION("IF(A25="""","""", IFERROR(TEXTJOIN("", ""&CHAR(10), TRUE, FILTER('All URLs'!A24:A522, 'All URLs'!B24:B522=A25, 'All URLs'!A24:A522<>"""") ),"""") ) "),"") | E25: 691-720
A26: P24 | D26: =IFERROR(__xludf.DUMMYFUNCTION("IF(A26="""","""", IFERROR(TEXTJOIN("", ""&CHAR(10), TRUE, FILTER('All URLs'!A25:A523, 'All URLs'!B25:B523=A26, 'All URLs'!A25:A523<>"""") ),"""") ) "),"") | E26: 721-750
A27: P25 | D27: =IFERROR(__xludf.DUMMYFUNCTION("IF(A27="""","""", IFERROR(TEXTJOIN("", ""&CHAR(10), TRUE, FILTER('All URLs'!A26:A524, 'All URLs'!B26:B524=A27, 'All URLs'!A26:A524<>"""") ),"""") ) "),"") | E27: 751-780
A28: P26 | D28: =IFERROR(__xludf.DUMMYFUNCTION("IF(A28="""","""", IFERROR(TEXTJOIN("", ""&CHAR(10), TRUE, FILTER('All URLs'!A27:A525, 'All URLs'!B27:B525=A28, 'All URLs'!A27:A525<>"""") ),"""") ) "),"")
A29: P27 | D29: =IFERROR(__xludf.DUMMYFUNCTION("IF(A29="""","""", IFERROR(TEXTJOIN("", ""&CHAR(10), TRUE, FILTER('All URLs'!A28:A526, 'All URLs'!B28:B526=A29, 'All URLs'!A28:A526<>"""") ),"""") ) "),"")
A30: P28 | D30: =IFERROR(__xludf.DUMMYFUNCTION("IF(A30="""","""", IFERROR(TEXTJOIN("", ""&CHAR(10), TRUE, FILTER('All URLs'!A29:A527, 'All URLs'!B29:B527=A30, 'All URLs'!A29:A527<>"""") ),"""") ) "),"")
A31: P29 | D31: =IFERROR(__xludf.DUMMYFUNCTION("IF(A31="""","""", IFERROR(TEXTJOIN("", ""&CHAR(10), TRUE, FILTER('All URLs'!A30:A528, 'All URLs'!B30:B528=A31, 'All URLs'!A30:A528<>"""") ),"""") ) "),"")
A32: P30 | D32: =IFERROR(__xludf.DUMMYFUNCTION("IF(A32="""","""", IFERROR(TEXTJOIN("", ""&CHAR(10), TRUE, FILTER('All URLs'!A31:A529, 'All URLs'!B31:B529=A32, 'All URLs'!A31:A529<>"""") ),"""") ) "),"")
A33: P31 | D33: =IFERROR(__xludf.DUMMYFUNCTION("IF(A33="""","""", IFERROR(TEXTJOIN("", ""&CHAR(10), TRUE, FILTER('All URLs'!A32:A530, 'All URLs'!B32:B530=A33, 'All URLs'!A32:A530<>"""") ),"""") ) "),"")
A34: P32 | D34: =IFERROR(__xludf.DUMMYFUNCTION("IF(A34="""","""", IFERROR(TEXTJOIN("", ""&CHAR(10), TRUE, FILTER('All URLs'!A33:A531, 'All URLs'!B33:B531=A34, 'All URLs'!A33:A531<>"""") ),"""") ) "),"")
A35: P33 | D35: =IFERROR(__xludf.DUMMYFUNCTION("IF(A35="""","""", IFERROR(TEXTJOIN("", ""&CHAR(10), TRUE, FILTER('All URLs'!A34:A532, 'All URLs'!B34:B532=A35, 'All URLs'!A34:A532<>"""") ),"""") ) "),"")
A36: P34 | D36: =IFERROR(__xludf.DUMMYFUNCTION("IF(A36="""","""", IFERROR(TEXTJOIN("", ""&CHAR(10), TRUE, FILTER('All URLs'!A35:A533, 'All URLs'!B35:B533=A36, 'All URLs'!A35:A533<>"""") ),"""") ) "),"")
A37: P35 | D37: =IFERROR(__xludf.DUMMYFUNCTION("IF(A37="""","""", IFERROR(TEXTJOIN("", ""&CHAR(10), TRUE, FILTER('All URLs'!A36:A534, 'All URLs'!B36:B534=A37, 'All URLs'!A36:A534<>"""") ),"""") ) "),"")
A38: P36 | D38: =IFERROR(__xludf.DUMMYFUNCTION("IF(A38="""","""", IFERROR(TEXTJOIN("", ""&CHAR(10), TRUE, FILTER('All URLs'!A37:A535, 'All URLs'!B37:B535=A38, 'All URLs'!A37:A535<>"""") ),"""") ) "),"")
A39: P37 | D39: =IFERROR(__xludf.DUMMYFUNCTION("IF(A39="""","""", IFERROR(TEXTJOIN("", ""&CHAR(10), TRUE, FILTER('All URLs'!A38:A536, 'All URLs'!B38:B536=A39, 'All URLs'!A38:A536<>"""") ),"""") ) "),"")
A40: P38 | D40: =IFERROR(__xludf.DUMMYFUNCTION("IF(A40="""","""", IFERROR(TEXTJOIN("", ""&CHAR(10), TRUE, FILTER('All URLs'!A39:A537, 'All URLs'!B39:B537=A40, 'All URLs'!A39:A537<>"""") ),"""") ) "),"")
...

Sheet All URLs
A1: URL | B1: Unique page No.

Sheet Final Report
A1: Page No | B1: Page Name | C1: Page URL | D1: Issue Title | E1: Test Findings | F1: Move to Report | G1: Actual Result | H1: Incorrect Code | I1: Screenshots | J1: Recommendation | K1: Correct Code | L1: Severity | M1: User Affected | N1: WCAG Success Criteria Number | O1: WCAG Success Criteria Name | P1: WCAG Conformance Level | Q1: GIGW 3.0 | R1: IS 17802 | S1: Chrome/JAWS | T1: Firefox/NVDA | U1: Edge/JAWS | V1: MAC - Safari/VoiceOver | W1: Android- Chrome/TalkBack | X1: iOS - Safari/VoiceOver | Y1: ZoomText | Z1: Dragon Natural Speaking | AA1: Developer's Status | AB1: Developer's Comment | AC1: Issue Reported by | AD1: Tester's Comment | AE1: Tester Status | AF1: QA Name | AG1: QA Coment | AH1: QA Status | AI1: Severity Rank | AJ1: Level Rank
B2: =IFERROR(__xludf.DUMMYFUNCTION("ARRAY_CONSTRAIN( ARRAYFORMULA( IF( 'Final Report'!A2="""", """", TEXTJOIN( "", "" & CHAR(10), TRUE, IFERROR( VLOOKUP( TRIM( SPLIT('Final Report'!A2, "","") ), "&" 'URL Details'!A:B, 2, FALSE ), """" ) ) ) ), 1, 1 ) "),"") | C2: =IFERROR(__xludf.DUMMYFUNCTION("IFERROR(IF('Final Report'!A2="""","""", TEXTJOIN(CHAR(10), TRUE, ARRAYFORMULA( ""• ""& FILTER( TRIM(FLATTEN(SPLIT( REGEXREPLACE( SUBSTITUTE(TEXTJOIN("","", TRUE, IFERROR(ARRAYFORMULA(VLOOKUP(TRIM(SPLIT('Final Report'!A2, "","")), 'URL Details'!A:D, 4, FAL"&"SE)),"""") ), CHAR(10), "",""), ""\s*,\s*"", "",""), "",""))), TRIM(FLATTEN(SPLIT( REGEXREPLACE( SUBSTITUTE(TEXTJOIN("","", TRUE, IFERROR(ARRAYFORMULA(VLOOKUP(TRIM(SPLIT('Final Report'!A2, "","")), 'URL Details'!A:D, 4, FALSE)),"""") ), CHAR(10), "",""), "&"""\s*,\s*"", "",""), "","")))<>"""" ) ) ) ),"""") "),"") | F2: FALSE | G2: =IF(F2=True, IFERROR(VLOOKUP(D2, Repository!A:B, 2, 0), ""), "") | J2: =IF(F2=True, IFERROR(VLOOKUP(D2, Repository!A:C, 3, 0), ""), "") | L2: =IF(F2=True, IFERROR(VLOOKUP(D2, Repository!A:E, 5, 0), ""), "") | N2: =IF(F2=True, IFERROR(VLOOKUP(D2, Repository!A:G, 7, 0), ""), "") | O2: =IFERROR(__xludf.DUMMYFUNCTION("ARRAY_CONSTRAIN( ARRAYFORMULA( IFERROR( LET( list, N2, arr, TRIM(SPLIT(list, "","")), names, XLOOKUP( arr, 'Conformance Score'!A:A, 'Conformance Score'!B:B, ""Not found"" "&"), TEXTJOIN("", "", TRUE, names) ), """" ) ), 1, 1 ) "),"") | P2: =IF(F2=True, IFERROR(VLOOKUP(D2, Repository!A:F, 6, 0), ""), "") | Q2: =IF(F2=True, IFERROR(VLOOKUP(D2, Repository!A:I, 8, 0), ""), "") | R2: =IF(F2=True, IFERROR(VLOOKUP(D2, Repository!A:J, 9, 0), ""), "") | AI2: =IF(L2="","", IF(L2="Blocker",1, IF(L2="Critical",2, IF(L2="Major",3, IF(L2="Minor",4,""))))) | AJ2: =IF(P2="","", IF(P2="A",1, IF(P2="AA",2, IF(P2="AAA",3,""))))
B3: =IFERROR(__xludf.DUMMYFUNCTION("ARRAY_CONSTRAIN( ARRAYFORMULA( IF( 'Final Report'!A3="""", """", TEXTJOIN( "", "" & CHAR(10), TRUE, IFERROR( VLOOKUP( TRIM( SPLIT('Final Report'!A3, "","") ), "&" 'URL Details'!A:B, 2, FALSE ), """" ) ) ) ), 1, 1 ) "),"") | C3: =IFERROR(__xludf.DUMMYFUNCTION("IFERROR(IF('Final Report'!A3="""","""", TEXTJOIN(CHAR(10), TRUE, ARRAYFORMULA( ""• ""& FILTER( TRIM(FLATTEN(SPLIT( REGEXREPLACE( SUBSTITUTE(TEXTJOIN("","", TRUE, IFERROR(ARRAYFORMULA(VLOOKUP(TRIM(SPLIT('Final Report'!A3, "","")), 'URL Details'!A:D, 4, FAL"&"SE)),"""") ), CHAR(10), "",""), ""\s*,\s*"", "",""), "",""))), TRIM(FLATTEN(SPLIT( REGEXREPLACE( SUBSTITUTE(TEXTJOIN("","", TRUE, IFERROR(ARRAYFORMULA(VLOOKUP(TRIM(SPLIT('Final Report'!A3, "","")), 'URL Details'!A:D, 4, FALSE)),"""") ), CHAR(10), "",""), "&"""\s*,\s*"", "",""), "","")))<>"""" ) ) ) ),"""") "),"") | F3: FALSE | G3: =IF(F3=True, IFERROR(VLOOKUP(D3, Repository!A:B, 2, 0), ""), "") | J3: =IF(F3=True, IFERROR(VLOOKUP(D3, Repository!A:C, 3, 0), ""), "") | L3: =IF(F3=True, IFERROR(VLOOKUP(D3, Repository!A:E, 5, 0), ""), "") | N3: =IF(F3=True, IFERROR(VLOOKUP(D3, Repository!A:G, 7, 0), ""), "") | O3: =IFERROR(__xludf.DUMMYFUNCTION("ARRAY_CONSTRAIN( ARRAYFORMULA( IFERROR( LET( list, N3, arr, TRIM(SPLIT(list, "","")), names, XLOOKUP( arr, 'Conformance Score'!A:A, 'Conformance Score'!B:B, ""Not found"" "&"), TEXTJOIN("", "", TRUE, names) ), """" ) ), 1, 1 ) "),"") | P3: =IF(F3="Yes", IFERROR(VLOOKUP(D3, Repository!A:F, 6, 0), ""), "") | Q3: =IF(F3="Yes", IFERROR(VLOOKUP(D3, Repository!A:I, 8, 0), ""), "") | R3: =IF(F3="Yes", IFERROR(VLOOKUP(D3, Repository!A:J, 9, 0), ""), "") | AI3: =IF(L3="","", IF(L3="Blocker",1, IF(L3="Critical",2, IF(L3="Major",3, IF(L3="Minor",4,""))))) | AJ3: =IF(P3="","", IF(P3="A",1, IF(P3="AA",2, IF(P3="AAA",3,""))))
B4: =IFERROR(__xludf.DUMMYFUNCTION("ARRAY_CONSTRAIN( ARRAYFORMULA( IF( 'Final Report'!A4="""", """", TEXTJOIN( "", "" & CHAR(10), TRUE, IFERROR( VLOOKUP( TRIM( SPLIT('Final Report'!A4, "","") ), "&" 'URL Details'!A:B, 2, FALSE ), """" ) ) ) ), 1, 1 ) "),"") | C4: =IFERROR(__xludf.DUMMYFUNCTION("IFERROR(IF('Final Report'!A4="""","""", TEXTJOIN(CHAR(10), TRUE, ARRAYFORMULA( ""• ""& FILTER( TRIM(FLATTEN(SPLIT( REGEXREPLACE( SUBSTITUTE(TEXTJOIN("","", TRUE, IFERROR(ARRAYFORMULA(VLOOKUP(TRIM(SPLIT('Final Report'!A4, "","")), 'URL Details'!A:D, 4, FAL"&"SE)),"""") ), CHAR(10), "",""), ""\s*,\s*"", "",""), "",""))), TRIM(FLATTEN(SPLIT( REGEXREPLACE( SUBSTITUTE(TEXTJOIN("","", TRUE, IFERROR(ARRAYFORMULA(VLOOKUP(TRIM(SPLIT('Final Report'!A4, "","")), 'URL Details'!A:D, 4, FALSE)),"""") ), CHAR(10), "",""), "&"""\s*,\s*"", "",""), "","")))<>"""" ) ) ) ),"""") "),"") | F4: FALSE | G4: =IF(F4=True, IFERROR(VLOOKUP(D4, Repository!A:B, 2, 0), ""), "") | J4: =IF(F4=True, IFERROR(VLOOKUP(D4, Repository!A:C, 3, 0), ""), "") | L4: =IF(F4=True, IFERROR(VLOOKUP(D4, Repository!A:E, 5, 0), ""), "") | N4: =IF(F4=True, IFERROR(VLOOKUP(D4, Repository!A:G, 7, 0), ""), "") | O4: =IFERROR(__xludf.DUMMYFUNCTION("ARRAY_CONSTRAIN( ARRAYFORMULA( IFERROR( LET( list, N4, arr, TRIM(SPLIT(list, "","")), names, XLOOKUP( arr, 'Conformance Score'!A:A, 'Conformance Score'!B:B, ""Not found"" "&"), TEXTJOIN("", "", TRUE, names) ), """" ) ), 1, 1 ) "),"") | P4: =IF(F4="Yes", IFERROR(VLOOKUP(D4, Repository!A:F, 6, 0), ""), "") | Q4: =IF(F4="Yes", IFERROR(VLOOKUP(D4, Repository!A:I, 8, 0), ""), "") | R4: =IF(F4="Yes", IFERROR(VLOOKUP(D4, Repository!A:J, 9, 0), ""), "") | AI4: =IF(L4="","", IF(L4="Blocker",1, IF(L4="Critical",2, IF(L4="Major",3, IF(L4="Minor",4,""))))) | AJ4: =IF(P4="","", IF(P4="A",1, IF(P4="AA",2, IF(P4="AAA",3,""))))
B5: =IFERROR(__xludf.DUMMYFUNCTION("ARRAY_CONSTRAIN( ARRAYFORMULA( IF( 'Final Report'!A5="""", """", TEXTJOIN( "", "" & CHAR(10), TRUE, IFERROR( VLOOKUP( TRIM( SPLIT('Final Report'!A5, "","") ), "&" 'URL Details'!A:B, 2, FALSE ), """" ) ) ) ), 1, 1 ) "),"") | C5: =IFERROR(__xludf.DUMMYFUNCTION("IFERROR(IF('Final Report'!A5="""","""", TEXTJOIN(CHAR(10), TRUE, ARRAYFORMULA( ""• ""& FILTER( TRIM(FLATTEN(SPLIT( REGEXREPLACE( SUBSTITUTE(TEXTJOIN("","", TRUE, IFERROR(ARRAYFORMULA(VLOOKUP(TRIM(SPLIT('Final Report'!A5, "","")), 'URL Details'!A:D, 4, FAL"&"SE)),"""") ), CHAR(10), "",""), ""\s*,\s*"", "",""), "",""))), TRIM(FLATTEN(SPLIT( REGEXREPLACE( SUBSTITUTE(TEXTJOIN("","", TRUE, IFERROR(ARRAYFORMULA(VLOOKUP(TRIM(SPLIT('Final Report'!A5, "","")), 'URL Details'!A:D, 4, FALSE)),"""") ), CHAR(10), "",""), "&"""\s*,\s*"", "",""), "","")))<>"""" ) ) ) ),"""") "),"") | F5: FALSE | G5: =IF(F5=True, IFERROR(VLOOKUP(D5, Repository!A:B, 2, 0), ""), "") | J5: =IF(F5=True, IFERROR(VLOOKUP(D5, Repository!A:C, 3, 0), ""), "") | L5: =IF(F5=True, IFERROR(VLOOKUP(D5, Repository!A:E, 5, 0), ""), "") | N5: =IF(F5=True, IFERROR(VLOOKUP(D5, Repository!A:G, 7, 0), ""), "") | O5: =IFERROR(__xludf.DUMMYFUNCTION("ARRAY_CONSTRAIN( ARRAYFORMULA( IFERROR( LET( list, N5, arr, TRIM(SPLIT(list, "","")), names, XLOOKUP( arr, 'Conformance Score'!A:A, 'Conformance Score'!B:B, ""Not found"" "&"), TEXTJOIN("", "", TRUE, names) ), """" ) ), 1, 1 ) "),"") | P5: =IF(F5="Yes", IFERROR(VLOOKUP(D5, Repository!A:F, 6, 0), ""), "") | Q5: =IF(F5="Yes", IFERROR(VLOOKUP(D5, Repository!A:I, 8, 0), ""), "") | R5: =IF(F5="Yes", IFERROR(VLOOKUP(D5, Repository!A:J, 9, 0), ""), "") | AI5: =IF(L5="","", IF(L5="Blocker",1, IF(L5="Critical",2, IF(L5="Major",3, IF(L5="Minor",4,""))))) | AJ5: =IF(P5="","", IF(P5="A",1, IF(P5="AA",2, IF(P5="AAA",3,""))))
B6: =IFERROR(__xludf.DUMMYFUNCTION("ARRAY_CONSTRAIN( ARRAYFORMULA( IF( 'Final Report'!A6="""", """", TEXTJOIN( "", "" & CHAR(10), TRUE, IFERROR( VLOOKUP( TRIM( SPLIT('Final Report'!A6, "","") ), "&" 'URL Details'!A:B, 2, FALSE ), """" ) ) ) ), 1, 1 ) "),"") | C6: =IFERROR(__xludf.DUMMYFUNCTION("IFERROR(IF('Final Report'!A6="""","""", TEXTJOIN(CHAR(10), TRUE, ARRAYFORMULA( ""• ""& FILTER( TRIM(FLATTEN(SPLIT( REGEXREPLACE( SUBSTITUTE(TEXTJOIN("","", TRUE, IFERROR(ARRAYFORMULA(VLOOKUP(TRIM(SPLIT('Final Report'!A6, "","")), 'URL Details'!A:D, 4, FAL"&"SE)),"""") ), CHAR(10), "",""), ""\s*,\s*"", "",""), "",""))), TRIM(FLATTEN(SPLIT( REGEXREPLACE( SUBSTITUTE(TEXTJOIN("","", TRUE, IFERROR(ARRAYFORMULA(VLOOKUP(TRIM(SPLIT('Final Report'!A6, "","")), 'URL Details'!A:D, 4, FALSE)),"""") ), CHAR(10), "",""), "&"""\s*,\s*"", "",""), "","")))<>"""" ) ) ) ),"""") "),"") | F6: FALSE | G6: =IF(F6=True, IFERROR(VLOOKUP(D6, Repository!A:B, 2, 0), ""), "") | J6: =IF(F6=True, IFERROR(VLOOKUP(D6, Repository!A:C, 3, 0), ""), "") | L6: =IF(F6=True, IFERROR(VLOOKUP(D6, Repository!A:E, 5, 0), ""), "") | N6: =IF(F6=True, IFERROR(VLOOKUP(D6, Repository!A:G, 7, 0), ""), "") | O6: =IFERROR(__xludf.DUMMYFUNCTION("ARRAY_CONSTRAIN( ARRAYFORMULA( IFERROR( LET( list, N6, arr, TRIM(SPLIT(list, "","")), names, XLOOKUP( arr, 'Conformance Score'!A:A, 'Conformance Score'!B:B, ""Not found"" "&"), TEXTJOIN("", "", TRUE, names) ), """" ) ), 1, 1 ) "),"") | P6: =IF(F6="Yes", IFERROR(VLOOKUP(D6, Repository!A:F, 6, 0), ""), "") | Q6: =IF(F6="Yes", IFERROR(VLOOKUP(D6, Repository!A:I, 8, 0), ""), "") | R6: =IF(F6="Yes", IFERROR(VLOOKUP(D6, Repository!A:J, 9, 0), ""), "") | AI6: =IF(L6="","", IF(L6="Blocker",1, IF(L6="Critical",2, IF(L6="Major",3, IF(L6="Minor",4,""))))) | AJ6: =IF(P6="","", IF(P6="A",1, IF(P6="AA",2, IF(P6="AAA",3,""))))
B7: =IFERROR(__xludf.DUMMYFUNCTION("ARRAY_CONSTRAIN( ARRAYFORMULA( IF( 'Final Report'!A7="""", """", TEXTJOIN( "", "" & CHAR(10), TRUE, IFERROR( VLOOKUP( TRIM( SPLIT('Final Report'!A7, "","") ), "&" 'URL Details'!A:B, 2, FALSE ), """" ) ) ) ), 1, 1 ) "),"") | C7: =IFERROR(__xludf.DUMMYFUNCTION("IFERROR(IF('Final Report'!A7="""","""", TEXTJOIN(CHAR(10), TRUE, ARRAYFORMULA( ""• ""& FILTER( TRIM(FLATTEN(SPLIT( REGEXREPLACE( SUBSTITUTE(TEXTJOIN("","", TRUE, IFERROR(ARRAYFORMULA(VLOOKUP(TRIM(SPLIT('Final Report'!A7, "","")), 'URL Details'!A:D, 4, FAL"&"SE)),"""") ), CHAR(10), "",""), ""\s*,\s*"", "",""), "",""))), TRIM(FLATTEN(SPLIT( REGEXREPLACE( SUBSTITUTE(TEXTJOIN("","", TRUE, IFERROR(ARRAYFORMULA(VLOOKUP(TRIM(SPLIT('Final Report'!A7, "","")), 'URL Details'!A:D, 4, FALSE)),"""") ), CHAR(10), "",""), "&"""\s*,\s*"", "",""), "","")))<>"""" ) ) ) ),"""") "),"") | F7: FALSE | G7: =IF(F7=True, IFERROR(VLOOKUP(D7, Repository!A:B, 2, 0), ""), "") | J7: =IF(F7=True, IFERROR(VLOOKUP(D7, Repository!A:C, 3, 0), ""), "") | L7: =IF(F7=True, IFERROR(VLOOKUP(D7, Repository!A:E, 5, 0), ""), "") | N7: =IF(F7=True, IFERROR(VLOOKUP(D7, Repository!A:G, 7, 0), ""), "") | O7: =IFERROR(__xludf.DUMMYFUNCTION("ARRAY_CONSTRAIN( ARRAYFORMULA( IFERROR( LET( list, N7, arr, TRIM(SPLIT(list, "","")), names, XLOOKUP( arr, 'Conformance Score'!A:A, 'Conformance Score'!B:B, ""Not found"" "&"), TEXTJOIN("", "", TRUE, names) ), """" ) ), 1, 1 ) "),"") | P7: =IF(F7="Yes", IFERROR(VLOOKUP(D7, Repository!A:F, 6, 0), ""), "") | Q7: =IF(F7="Yes", IFERROR(VLOOKUP(D7, Repository!A:I, 8, 0), ""), "") | R7: =IF(F7="Yes", IFERROR(VLOOKUP(D7, Repository!A:J, 9, 0), ""), "") | AI7: =IF(L7="","", IF(L7="Blocker",1, IF(L7="Critical",2, IF(L7="Major",3, IF(L7="Minor",4,""))))) | AJ7: =IF(P7="","", IF(P7="A",1, IF(P7="AA",2, IF(P7="AAA",3,""))))
B8: =IFERROR(__xludf.DUMMYFUNCTION("ARRAY_CONSTRAIN( ARRAYFORMULA( IF( 'Final Report'!A8="""", """", TEXTJOIN( "", "" & CHAR(10), TRUE, IFERROR( VLOOKUP( TRIM( SPLIT('Final Report'!A8, "","") ), "&" 'URL Details'!A:B, 2, FALSE ), """" ) ) ) ), 1, 1 ) "),"") | C8: =IFERROR(__xludf.DUMMYFUNCTION("IFERROR(IF('Final Report'!A8="""","""", TEXTJOIN(CHAR(10), TRUE, ARRAYFORMULA( ""• ""& FILTER( TRIM(FLATTEN(SPLIT( REGEXREPLACE( SUBSTITUTE(TEXTJOIN("","", TRUE, IFERROR(ARRAYFORMULA(VLOOKUP(TRIM(SPLIT('Final Report'!A8, "","")), 'URL Details'!A:D, 4, FAL"&"SE)),"""") ), CHAR(10), "",""), ""\s*,\s*"", "",""), "",""))), TRIM(FLATTEN(SPLIT( REGEXREPLACE( SUBSTITUTE(TEXTJOIN("","", TRUE, IFERROR(ARRAYFORMULA(VLOOKUP(TRIM(SPLIT('Final Report'!A8, "","")), 'URL Details'!A:D, 4, FALSE)),"""") ), CHAR(10), "",""), "&"""\s*,\s*"", "",""), "","")))<>"""" ) ) ) ),"""") "),"") | F8: FALSE | G8: =IF(F8=True, IFERROR(VLOOKUP(D8, Repository!A:B, 2, 0), ""), "") | J8: =IF(F8=True, IFERROR(VLOOKUP(D8, Repository!A:C, 3, 0), ""), "") | L8: =IF(F8=True, IFERROR(VLOOKUP(D8, Repository!A:E, 5, 0), ""), "") | N8: =IF(F8=True, IFERROR(VLOOKUP(D8, Repository!A:G, 7, 0), ""), "") | O8: =IFERROR(__xludf.DUMMYFUNCTION("ARRAY_CONSTRAIN( ARRAYFORMULA( IFERROR( LET( list, N8, arr, TRIM(SPLIT(list, "","")), names, XLOOKUP( arr, 'Conformance Score'!A:A, 'Conformance Score'!B:B, ""Not found"" "&"), TEXTJOIN("", "", TRUE, names) ), """" ) ), 1, 1 ) "),"") | P8: =IF(F8="Yes", IFERROR(VLOOKUP(D8, Repository!A:F, 6, 0), ""), "") | Q8: =IF(F8="Yes", IFERROR(VLOOKUP(D8, Repository!A:I, 8, 0), ""), "") | R8: =IF(F8="Yes", IFERROR(VLOOKUP(D8, Repository!A:J, 9, 0), ""), "") | AI8: =IF(L8="","", IF(L8="Blocker",1, IF(L8="Critical",2, IF(L8="Major",3, IF(L8="Minor",4,""))))) | AJ8: =IF(P8="","", IF(P8="A",1, IF(P8="AA",2, IF(P8="AAA",3,""))))
B9: =IFERROR(__xludf.DUMMYFUNCTION("ARRAY_CONSTRAIN( ARRAYFORMULA( IF( 'Final Report'!A9="""", """", TEXTJOIN( "", "" & CHAR(10), TRUE, IFERROR( VLOOKUP( TRIM( SPLIT('Final Report'!A9, "","") ), "&" 'URL Details'!A:B, 2, FALSE ), """" ) ) ) ), 1, 1 ) "),"") | C9: =IFERROR(__xludf.DUMMYFUNCTION("IFERROR(IF('Final Report'!A9="""","""", TEXTJOIN(CHAR(10), TRUE, ARRAYFORMULA( ""• ""& FILTER( TRIM(FLATTEN(SPLIT( REGEXREPLACE( SUBSTITUTE(TEXTJOIN("","", TRUE, IFERROR(ARRAYFORMULA(VLOOKUP(TRIM(SPLIT('Final Report'!A9, "","")), 'URL Details'!A:D, 4, FAL"&"SE)),"""") ), CHAR(10), "",""), ""\s*,\s*"", "",""), "",""))), TRIM(FLATTEN(SPLIT( REGEXREPLACE( SUBSTITUTE(TEXTJOIN("","", TRUE, IFERROR(ARRAYFORMULA(VLOOKUP(TRIM(SPLIT('Final Report'!A9, "","")), 'URL Details'!A:D, 4, FALSE)),"""") ), CHAR(10), "",""), "&"""\s*,\s*"", "",""), "","")))<>"""" ) ) ) ),"""") "),"") | F9: FALSE | G9: =IF(F9=True, IFERROR(VLOOKUP(D9, Repository!A:B, 2, 0), ""), "") | J9: =IF(F9=True, IFERROR(VLOOKUP(D9, Repository!A:C, 3, 0), ""), "") | L9: =IF(F9=True, IFERROR(VLOOKUP(D9, Repository!A:E, 5, 0), ""), "") | N9: =IF(F9=True, IFERROR(VLOOKUP(D9, Repository!A:G, 7, 0), ""), "") | O9: =IFERROR(__xludf.DUMMYFUNCTION("ARRAY_CONSTRAIN( ARRAYFORMULA( IFERROR( LET( list, N9, arr, TRIM(SPLIT(list, "","")), names, XLOOKUP( arr, 'Conformance Score'!A:A, 'Conformance Score'!B:B, ""Not found"" "&"), TEXTJOIN("", "", TRUE, names) ), """" ) ), 1, 1 ) "),"") | P9: =IF(F9="Yes", IFERROR(VLOOKUP(D9, Repository!A:F, 6, 0), ""), "") | Q9: =IF(F9="Yes", IFERROR(VLOOKUP(D9, Repository!A:I, 8, 0), ""), "") | R9: =IF(F9="Yes", IFERROR(VLOOKUP(D9, Repository!A:J, 9, 0), ""), "") | AI9: =IF(L9="","", IF(L9="Blocker",1, IF(L9="Critical",2, IF(L9="Major",3, IF(L9="Minor",4,""))))) | AJ9: =IF(P9="","", IF(P9="A",1, IF(P9="AA",2, IF(P9="AAA",3,""))))
B10: =IFERROR(__xludf.DUMMYFUNCTION("ARRAY_CONSTRAIN( ARRAYFORMULA( IF( 'Final Report'!A10="""", """", TEXTJOIN( "", "" & CHAR(10), TRUE, IFERROR( VLOOKUP( TRIM( SPLIT('Final Report'!A10, "","") )"&", 'URL Details'!A:B, 2, FALSE ), """" ) ) ) ), 1, 1 ) "),"") | C10: =IFERROR(__xludf.DUMMYFUNCTION("IFERROR(IF('Final Report'!A10="""","""", TEXTJOIN(CHAR(10), TRUE, ARRAYFORMULA( ""• ""& FILTER( TRIM(FLATTEN(SPLIT( REGEXREPLACE( SUBSTITUTE(TEXTJOIN("","", TRUE, IFERROR(ARRAYFORMULA(VLOOKUP(TRIM(SPLIT('Final Report'!A10, "","")), 'URL Details'!A:D, 4, F"&"ALSE)),"""") ), CHAR(10), "",""), ""\s*,\s*"", "",""), "",""))), TRIM(FLATTEN(SPLIT( REGEXREPLACE( SUBSTITUTE(TEXTJOIN("","", TRUE, IFERROR(ARRAYFORMULA(VLOOKUP(TRIM(SPLIT('Final Report'!A10, "","")), 'URL Details'!A:D, 4, FALSE)),"""") ), CHAR(10), "","""&"), ""\s*,\s*"", "",""), "","")))<>"""" ) ) ) ),"""") "),"") | F10: FALSE | G10: =IF(F10=True, IFERROR(VLOOKUP(D10, Repository!A:B, 2, 0), ""), "") | J10: =IF(F10=True, IFERROR(VLOOKUP(D10, Repository!A:C, 3, 0), ""), "") | L10: =IF(F10=True, IFERROR(VLOOKUP(D10, Repository!A:E, 5, 0), ""), "") | N10: =IF(F10=True, IFERROR(VLOOKUP(D10, Repository!A:G, 7, 0), ""), "") | O10: =IFERROR(__xludf.DUMMYFUNCTION("ARRAY_CONSTRAIN( ARRAYFORMULA( IFERROR( LET( list, N10, arr, TRIM(SPLIT(list, "","")), names, XLOOKUP( arr, 'Conformance Score'!A:A, 'Conformance Score'!B:B, ""Not found"" "&" ), TEXTJOIN("", "", TRUE, names) ), """" ) ), 1, 1 ) "),"") | P10: =IF(F10="Yes", IFERROR(VLOOKUP(D10, Repository!A:F, 6, 0), ""), "") | Q10: =IF(F10="Yes", IFERROR(VLOOKUP(D10, Repository!A:I, 8, 0), ""), "") | R10: =IF(F10="Yes", IFERROR(VLOOKUP(D10, Repository!A:J, 9, 0), ""), "") | AI10: =IF(L10="","", IF(L10="Blocker",1, IF(L10="Critical",2, IF(L10="Major",3, IF(L10="Minor",4,""))))) | AJ10: =IF(P10="","", IF(P10="A",1, IF(P10="AA",2, IF(P10="AAA",3,""))))
B11: =IFERROR(__xludf.DUMMYFUNCTION("ARRAY_CONSTRAIN( ARRAYFORMULA( IF( 'Final Report'!A11="""", """", TEXTJOIN( "", "" & CHAR(10), TRUE, IFERROR( VLOOKUP( TRIM( SPLIT('Final Report'!A11, "","") )"&", 'URL Details'!A:B, 2, FALSE ), """" ) ) ) ), 1, 1 ) "),"") | C11: =IFERROR(__xludf.DUMMYFUNCTION("IFERROR(IF('Final Report'!A11="""","""", TEXTJOIN(CHAR(10), TRUE, ARRAYFORMULA( ""• ""& FILTER( TRIM(FLATTEN(SPLIT( REGEXREPLACE( SUBSTITUTE(TEXTJOIN("","", TRUE, IFERROR(ARRAYFORMULA(VLOOKUP(TRIM(SPLIT('Final Report'!A11, "","")), 'URL Details'!A:D, 4, F"&"ALSE)),"""") ), CHAR(10), "",""), ""\s*,\s*"", "",""), "",""))), TRIM(FLATTEN(SPLIT( REGEXREPLACE( SUBSTITUTE(TEXTJOIN("","", TRUE, IFERROR(ARRAYFORMULA(VLOOKUP(TRIM(SPLIT('Final Report'!A11, "","")), 'URL Details'!A:D, 4, FALSE)),"""") ), CHAR(10), "","""&"), ""\s*,\s*"", "",""), "","")))<>"""" ) ) ) ),"""") "),"") | F11: FALSE | G11: =IF(F11=True, IFERROR(VLOOKUP(D11, Repository!A:B, 2, 0), ""), "") | J11: =IF(F11=True, IFERROR(VLOOKUP(D11, Repository!A:C, 3, 0), ""), "") | L11: =IF(F11=True, IFERROR(VLOOKUP(D11, Repository!A:E, 5, 0), ""), "") | N11: =IF(F11=True, IFERROR(VLOOKUP(D11, Repository!A:G, 7, 0), ""), "") | O11: =IFERROR(__xludf.DUMMYFUNCTION("ARRAY_CONSTRAIN( ARRAYFORMULA( IFERROR( LET( list, N11, arr, TRIM(SPLIT(list, "","")), names, XLOOKUP( arr, 'Conformance Score'!A:A, 'Conformance Score'!B:B, ""Not found"" "&" ), TEXTJOIN("", "", TRUE, names) ), """" ) ), 1, 1 ) "),"") | P11: =IF(F11="Yes", IFERROR(VLOOKUP(D11, Repository!A:F, 6, 0), ""), "") | Q11: =IF(F11="Yes", IFERROR(VLOOKUP(D11, Repository!A:I, 8, 0), ""), "") | R11: =IF(F11="Yes", IFERROR(VLOOKUP(D11, Repository!A:J, 9, 0), ""), "") | AI11: =IF(L11="","", IF(L11="Blocker",1, IF(L11="Critical",2, IF(L11="Major",3, IF(L11="Minor",4,""))))) | AJ11: =IF(P11="","", IF(P11="A",1, IF(P11="AA",2, IF(P11="AAA",3,""))))
B12: =IFERROR(__xludf.DUMMYFUNCTION("ARRAY_CONSTRAIN( ARRAYFORMULA( IF( 'Final Report'!A12="""", """", TEXTJOIN( "", "" & CHAR(10), TRUE, IFERROR( VLOOKUP( TRIM( SPLIT('Final Report'!A12, "","") )"&", 'URL Details'!A:B, 2, FALSE ), """" ) ) ) ), 1, 1 ) "),"") | C12: =IFERROR(__xludf.DUMMYFUNCTION("IFERROR(IF('Final Report'!A12="""","""", TEXTJOIN(CHAR(10), TRUE, ARRAYFORMULA( ""• ""& FILTER( TRIM(FLATTEN(SPLIT( REGEXREPLACE( SUBSTITUTE(TEXTJOIN("","", TRUE, IFERROR(ARRAYFORMULA(VLOOKUP(TRIM(SPLIT('Final Report'!A12, "","")), 'URL Details'!A:D, 4, F"&"ALSE)),"""") ), CHAR(10), "",""), ""\s*,\s*"", "",""), "",""))), TRIM(FLATTEN(SPLIT( REGEXREPLACE( SUBSTITUTE(TEXTJOIN("","", TRUE, IFERROR(ARRAYFORMULA(VLOOKUP(TRIM(SPLIT('Final Report'!A12, "","")), 'URL Details'!A:D, 4, FALSE)),"""") ), CHAR(10), "","""&"), ""\s*,\s*"", "",""), "","")))<>"""" ) ) ) ),"""") "),"") | F12: FALSE | G12: =IF(F12=True, IFERROR(VLOOKUP(D12, Repository!A:B, 2, 0), ""), "") | J12: =IF(F12=True, IFERROR(VLOOKUP(D12, Repository!A:C, 3, 0), ""), "") | L12: =IF(F12=True, IFERROR(VLOOKUP(D12, Repository!A:E, 5, 0), ""), "") | N12: =IF(F12=True, IFERROR(VLOOKUP(D12, Repository!A:G, 7, 0), ""), "") | O12: =IFERROR(__xludf.DUMMYFUNCTION("ARRAY_CONSTRAIN( ARRAYFORMULA( IFERROR( LET( list, N12, arr, TRIM(SPLIT(list, "","")), names, XLOOKUP( arr, 'Conformance Score'!A:A, 'Conformance Score'!B:B, ""Not found"" "&" ), TEXTJOIN("", "", TRUE, names) ), """" ) ), 1, 1 ) "),"") | P12: =IF(F12="Yes", IFERROR(VLOOKUP(D12, Repository!A:F, 6, 0), ""), "") | Q12: =IF(F12="Yes", IFERROR(VLOOKUP(D12, Repository!A:I, 8, 0), ""), "") | R12: =IF(F12="Yes", IFERROR(VLOOKUP(D12, Repository!A:J, 9, 0), ""), "") | AI12: =IF(L12="","", IF(L12="Blocker",1, IF(L12="Critical",2, IF(L12="Major",3, IF(L12="Minor",4,""))))) | AJ12: =IF(P12="","", IF(P12="A",1, IF(P12="AA",2, IF(P12="AAA",3,""))))
B13: =IFERROR(__xludf.DUMMYFUNCTION("ARRAY_CONSTRAIN( ARRAYFORMULA( IF( 'Final Report'!A13="""", """", TEXTJOIN( "", "" & CHAR(10), TRUE, IFERROR( VLOOKUP( TRIM( SPLIT('Final Report'!A13, "","") )"&", 'URL Details'!A:B, 2, FALSE ), """" ) ) ) ), 1, 1 ) "),"") | C13: =IFERROR(__xludf.DUMMYFUNCTION("IFERROR(IF('Final Report'!A13="""","""", TEXTJOIN(CHAR(10), TRUE, ARRAYFORMULA( ""• ""& FILTER( TRIM(FLATTEN(SPLIT( REGEXREPLACE( SUBSTITUTE(TEXTJOIN("","", TRUE, IFERROR(ARRAYFORMULA(VLOOKUP(TRIM(SPLIT('Final Report'!A13, "","")), 'URL Details'!A:D, 4, F"&"ALSE)),"""") ), CHAR(10), "",""), ""\s*,\s*"", "",""), "",""))), TRIM(FLATTEN(SPLIT( REGEXREPLACE( SUBSTITUTE(TEXTJOIN("","", TRUE, IFERROR(ARRAYFORMULA(VLOOKUP(TRIM(SPLIT('Final Report'!A13, "","")), 'URL Details'!A:D, 4, FALSE)),"""") ), CHAR(10), "","""&"), ""\s*,\s*"", "",""), "","")))<>"""" ) ) ) ),"""") "),"") | F13: FALSE | G13: =IF(F13=True, IFERROR(VLOOKUP(D13, Repository!A:B, 2, 0), ""), "") | J13: =IF(F13=True, IFERROR(VLOOKUP(D13, Repository!A:C, 3, 0), ""), "") | L13: =IF(F13=True, IFERROR(VLOOKUP(D13, Repository!A:E, 5, 0), ""), "") | N13: =IF(F13=True, IFERROR(VLOOKUP(D13, Repository!A:G, 7, 0), ""), "") | O13: =IFERROR(__xludf.DUMMYFUNCTION("ARRAY_CONSTRAIN( ARRAYFORMULA( IFERROR( LET( list, N13, arr, TRIM(SPLIT(list, "","")), names, XLOOKUP( arr, 'Conformance Score'!A:A, 'Conformance Score'!B:B, ""Not found"" "&" ), TEXTJOIN("", "", TRUE, names) ), """" ) ), 1, 1 ) "),"") | P13: =IF(F13="Yes", IFERROR(VLOOKUP(D13, Repository!A:F, 6, 0), ""), "") | Q13: =IF(F13="Yes", IFERROR(VLOOKUP(D13, Repository!A:I, 8, 0), ""), "") | R13: =IF(F13="Yes", IFERROR(VLOOKUP(D13, Repository!A:J, 9, 0), ""), "") | AI13: =IF(L13="","", IF(L13="Blocker",1, IF(L13="Critical",2, IF(L13="Major",3, IF(L13="Minor",4,""))))) | AJ13: =IF(P13="","", IF(P13="A",1, IF(P13="AA",2, IF(P13="AAA",3,""))))
B14: =IFERROR(__xludf.DUMMYFUNCTION("ARRAY_CONSTRAIN( ARRAYFORMULA( IF( 'Final Report'!A14="""", """", TEXTJOIN( "", "" & CHAR(10), TRUE, IFERROR( VLOOKUP( TRIM( SPLIT('Final Report'!A14, "","") )"&", 'URL Details'!A:B, 2, FALSE ), """" ) ) ) ), 1, 1 ) "),"") | C14: =IFERROR(__xludf.DUMMYFUNCTION("IFERROR(IF('Final Report'!A14="""","""", TEXTJOIN(CHAR(10), TRUE, ARRAYFORMULA( ""• ""& FILTER( TRIM(FLATTEN(SPLIT( REGEXREPLACE( SUBSTITUTE(TEXTJOIN("","", TRUE, IFERROR(ARRAYFORMULA(VLOOKUP(TRIM(SPLIT('Final Report'!A14, "","")), 'URL Details'!A:D, 4, F"&"ALSE)),"""") ), CHAR(10), "",""), ""\s*,\s*"", "",""), "",""))), TRIM(FLATTEN(SPLIT( REGEXREPLACE( SUBSTITUTE(TEXTJOIN("","", TRUE, IFERROR(ARRAYFORMULA(VLOOKUP(TRIM(SPLIT('Final Report'!A14, "","")), 'URL Details'!A:D, 4, FALSE)),"""") ), CHAR(10), "","""&"), ""\s*,\s*"", "",""), "","")))<>"""" ) ) ) ),"""") "),"") | F14: FALSE | G14: =IF(F14=True, IFERROR(VLOOKUP(D14, Repository!A:B, 2, 0), ""), "") | J14: =IF(F14=True, IFERROR(VLOOKUP(D14, Repository!A:C, 3, 0), ""), "") | L14: =IF(F14=True, IFERROR(VLOOKUP(D14, Repository!A:E, 5, 0), ""), "") | N14: =IF(F14=True, IFERROR(VLOOKUP(D14, Repository!A:G, 7, 0), ""), "") | O14: =IFERROR(__xludf.DUMMYFUNCTION("ARRAY_CONSTRAIN( ARRAYFORMULA( IFERROR( LET( list, N14, arr, TRIM(SPLIT(list, "","")), names, XLOOKUP( arr, 'Conformance Score'!A:A, 'Conformance Score'!B:B, ""Not found"" "&" ), TEXTJOIN("", "", TRUE, names) ), """" ) ), 1, 1 ) "),"") | P14: =IF(F14="Yes", IFERROR(VLOOKUP(D14, Repository!A:F, 6, 0), ""), "") | Q14: =IF(F14="Yes", IFERROR(VLOOKUP(D14, Repository!A:I, 8, 0), ""), "") | R14: =IF(F14="Yes", IFERROR(VLOOKUP(D14, Repository!A:J, 9, 0), ""), "") | AI14: =IF(L14="","", IF(L14="Blocker",1, IF(L14="Critical",2, IF(L14="Major",3, IF(L14="Minor",4,""))))) | AJ14: =IF(P14="","", IF(P14="A",1, IF(P14="AA",2, IF(P14="AAA",3,""))))
B15: =IFERROR(__xludf.DUMMYFUNCTION("ARRAY_CONSTRAIN( ARRAYFORMULA( IF( 'Final Report'!A15="""", """", TEXTJOIN( "", "" & CHAR(10), TRUE, IFERROR( VLOOKUP( TRIM( SPLIT('Final Report'!A15, "","") )"&", 'URL Details'!A:B, 2, FALSE ), """" ) ) ) ), 1, 1 ) "),"") | C15: =IFERROR(__xludf.DUMMYFUNCTION("IFERROR(IF('Final Report'!A15="""","""", TEXTJOIN(CHAR(10), TRUE, ARRAYFORMULA( ""• ""& FILTER( TRIM(FLATTEN(SPLIT( REGEXREPLACE( SUBSTITUTE(TEXTJOIN("","", TRUE, IFERROR(ARRAYFORMULA(VLOOKUP(TRIM(SPLIT('Final Report'!A15, "","")), 'URL Details'!A:D, 4, F"&"ALSE)),"""") ), CHAR(10), "",""), ""\s*,\s*"", "",""), "",""))), TRIM(FLATTEN(SPLIT( REGEXREPLACE( SUBSTITUTE(TEXTJOIN("","", TRUE, IFERROR(ARRAYFORMULA(VLOOKUP(TRIM(SPLIT('Final Report'!A15, "","")), 'URL Details'!A:D, 4, FALSE)),"""") ), CHAR(10), "","""&"), ""\s*,\s*"", "",""), "","")))<>"""" ) ) ) ),"""") "),"") | F15: FALSE | G15: =IF(F15=True, IFERROR(VLOOKUP(D15, Repository!A:B, 2, 0), ""), "") | J15: =IF(F15=True, IFERROR(VLOOKUP(D15, Repository!A:C, 3, 0), ""), "") | L15: =IF(F15=True, IFERROR(VLOOKUP(D15, Repository!A:E, 5, 0), ""), "") | N15: =IF(F15=True, IFERROR(VLOOKUP(D15, Repository!A:G, 7, 0), ""), "") | O15: =IFERROR(__xludf.DUMMYFUNCTION("ARRAY_CONSTRAIN( ARRAYFORMULA( IFERROR( LET( list, N15, arr, TRIM(SPLIT(list, "","")), names, XLOOKUP( arr, 'Conformance Score'!A:A, 'Conformance Score'!B:B, ""Not found"" "&" ), TEXTJOIN("", "", TRUE, names) ), """" ) ), 1, 1 ) "),"") | P15: =IF(F15="Yes", IFERROR(VLOOKUP(D15, Repository!A:F, 6, 0), ""), "") | Q15: =IF(F15="Yes", IFERROR(VLOOKUP(D15, Repository!A:I, 8, 0), ""), "") | R15: =IF(F15="Yes", IFERROR(VLOOKUP(D15, Repository!A:J, 9, 0), ""), "") | AI15: =IF(L15="","", IF(L15="Blocker",1, IF(L15="Critical",2, IF(L15="Major",3, IF(L15="Minor",4,""))))) | AJ15: =IF(P15="","", IF(P15="A",1, IF(P15="AA",2, IF(P15="AAA",3,""))))
B16: =IFERROR(__xludf.DUMMYFUNCTION("ARRAY_CONSTRAIN( ARRAYFORMULA( IF( 'Final Report'!A16="""", """", TEXTJOIN( "", "" & CHAR(10), TRUE, IFERROR( VLOOKUP( TRIM( SPLIT('Final Report'!A16, "","") )"&", 'URL Details'!A:B, 2, FALSE ), """" ) ) ) ), 1, 1 ) "),"") | C16: =IFERROR(__xludf.DUMMYFUNCTION("IFERROR(IF('Final Report'!A16="""","""", TEXTJOIN(CHAR(10), TRUE, ARRAYFORMULA( ""• ""& FILTER( TRIM(FLATTEN(SPLIT( REGEXREPLACE( SUBSTITUTE(TEXTJOIN("","", TRUE, IFERROR(ARRAYFORMULA(VLOOKUP(TRIM(SPLIT('Final Report'!A16, "","")), 'URL Details'!A:D, 4, F"&"ALSE)),"""") ), CHAR(10), "",""), ""\s*,\s*"", "",""), "",""))), TRIM(FLATTEN(SPLIT( REGEXREPLACE( SUBSTITUTE(TEXTJOIN("","", TRUE, IFERROR(ARRAYFORMULA(VLOOKUP(TRIM(SPLIT('Final Report'!A16, "","")), 'URL Details'!A:D, 4, FALSE)),"""") ), CHAR(10), "","""&"), ""\s*,\s*"", "",""), "","")))<>"""" ) ) ) ),"""") "),"") | F16: FALSE | G16: =IF(F16=True, IFERROR(VLOOKUP(D16, Repository!A:B, 2, 0), ""), "") | J16: =IF(F16=True, IFERROR(VLOOKUP(D16, Repository!A:C, 3, 0), ""), "") | L16: =IF(F16=True, IFERROR(VLOOKUP(D16, Repository!A:E, 5, 0), ""), "") | N16: =IF(F16=True, IFERROR(VLOOKUP(D16, Repository!A:G, 7, 0), ""), "") | O16: =IFERROR(__xludf.DUMMYFUNCTION("ARRAY_CONSTRAIN( ARRAYFORMULA( IFERROR( LET( list, N16, arr, TRIM(SPLIT(list, "","")), names, XLOOKUP( arr, 'Conformance Score'!A:A, 'Conformance Score'!B:B, ""Not found"" "&" ), TEXTJOIN("", "", TRUE, names) ), """" ) ), 1, 1 ) "),"") | P16: =IF(F16="Yes", IFERROR(VLOOKUP(D16, Repository!A:F, 6, 0), ""), "") | Q16: =IF(F16="Yes", IFERROR(VLOOKUP(D16, Repository!A:I, 8, 0), ""), "") | R16: =IF(F16="Yes", IFERROR(VLOOKUP(D16, Repository!A:J, 9, 0), ""), "") | AI16: =IF(L16="","", IF(L16="Blocker",1, IF(L16="Critical",2, IF(L16="Major",3, IF(L16="Minor",4,""))))) | AJ16: =IF(P16="","", IF(P16="A",1, IF(P16="AA",2, IF(P16="AAA",3,""))))
B17: =IFERROR(__xludf.DUMMYFUNCTION("ARRAY_CONSTRAIN( ARRAYFORMULA( IF( 'Final Report'!A17="""", """", TEXTJOIN( "", "" & CHAR(10), TRUE, IFERROR( VLOOKUP( TRIM( SPLIT('Final Report'!A17, "","") )"&", 'URL Details'!A:B, 2, FALSE ), """" ) ) ) ), 1, 1 ) "),"") | C17: =IFERROR(__xludf.DUMMYFUNCTION("IFERROR(IF('Final Report'!A17="""","""", TEXTJOIN(CHAR(10), TRUE, ARRAYFORMULA( ""• ""& FILTER( TRIM(FLATTEN(SPLIT( REGEXREPLACE( SUBSTITUTE(TEXTJOIN("","", TRUE, IFERROR(ARRAYFORMULA(VLOOKUP(TRIM(SPLIT('Final Report'!A17, "","")), 'URL Details'!A:D, 4, F"&"ALSE)),"""") ), CHAR(10), "",""), ""\s*,\s*"", "",""), "",""))), TRIM(FLATTEN(SPLIT( REGEXREPLACE( SUBSTITUTE(TEXTJOIN("","", TRUE, IFERROR(ARRAYFORMULA(VLOOKUP(TRIM(SPLIT('Final Report'!A17, "","")), 'URL Details'!A:D, 4, FALSE)),"""") ), CHAR(10), "","""&"), ""\s*,\s*"", "",""), "","")))<>"""" ) ) ) ),"""") "),"") | F17: FALSE | G17: =IF(F17=True, IFERROR(VLOOKUP(D17, Repository!A:B, 2, 0), ""), "") | J17: =IF(F17=True, IFERROR(VLOOKUP(D17, Repository!A:C, 3, 0), ""), "") | L17: =IF(F17=True, IFERROR(VLOOKUP(D17, Repository!A:E, 5, 0), ""), "") | N17: =IF(F17=True, IFERROR(VLOOKUP(D17, Repository!A:G, 7, 0), ""), "") | O17: =IFERROR(__xludf.DUMMYFUNCTION("ARRAY_CONSTRAIN( ARRAYFORMULA( IFERROR( LET( list, N17, arr, TRIM(SPLIT(list, "","")), names, XLOOKUP( arr, 'Conformance Score'!A:A, 'Conformance Score'!B:B, ""Not found"" "&" ), TEXTJOIN("", "", TRUE, names) ), """" ) ), 1, 1 ) "),"") | P17: =IF(F17="Yes", IFERROR(VLOOKUP(D17, Repository!A:F, 6, 0), ""), "") | Q17: =IF(F17="Yes", IFERROR(VLOOKUP(D17, Repository!A:I, 8, 0), ""), "") | R17: =IF(F17="Yes", IFERROR(VLOOKUP(D17, Repository!A:J, 9, 0), ""), "") | AI17: =IF(L17="","", IF(L17="Blocker",1, IF(L17="Critical",2, IF(L17="Major",3, IF(L17="Minor",4,""))))) | AJ17: =IF(P17="","", IF(P17="A",1, IF(P17="AA",2, IF(P17="AAA",3,""))))
B18: =IFERROR(__xludf.DUMMYFUNCTION("ARRAY_CONSTRAIN( ARRAYFORMULA( IF( 'Final Report'!A18="""", """", TEXTJOIN( "", "" & CHAR(10), TRUE, IFERROR( VLOOKUP( TRIM( SPLIT('Final Report'!A18, "","") )"&", 'URL Details'!A:B, 2, FALSE ), """" ) ) ) ), 1, 1 ) "),"") | C18: =IFERROR(__xludf.DUMMYFUNCTION("IFERROR(IF('Final Report'!A18="""","""", TEXTJOIN(CHAR(10), TRUE, ARRAYFORMULA( ""• ""& FILTER( TRIM(FLATTEN(SPLIT( REGEXREPLACE( SUBSTITUTE(TEXTJOIN("","", TRUE, IFERROR(ARRAYFORMULA(VLOOKUP(TRIM(SPLIT('Final Report'!A18, "","")), 'URL Details'!A:D, 4, F"&"ALSE)),"""") ), CHAR(10), "",""), ""\s*,\s*"", "",""), "",""))), TRIM(FLATTEN(SPLIT( REGEXREPLACE( SUBSTITUTE(TEXTJOIN("","", TRUE, IFERROR(ARRAYFORMULA(VLOOKUP(TRIM(SPLIT('Final Report'!A18, "","")), 'URL Details'!A:D, 4, FALSE)),"""") ), CHAR(10), "","""&"), ""\s*,\s*"", "",""), "","")))<>"""" ) ) ) ),"""") "),"") | F18: FALSE | G18: =IF(F18=True, IFERROR(VLOOKUP(D18, Repository!A:B, 2, 0), ""), "") | J18: =IF(F18=True, IFERROR(VLOOKUP(D18, Repository!A:C, 3, 0), ""), "") | L18: =IF(F18=True, IFERROR(VLOOKUP(D18, Repository!A:E, 5, 0), ""), "") | N18: =IF(F18=True, IFERROR(VLOOKUP(D18, Repository!A:G, 7, 0), ""), "") | O18: =IFERROR(__xludf.DUMMYFUNCTION("ARRAY_CONSTRAIN( ARRAYFORMULA( IFERROR( LET( list, N18, arr, TRIM(SPLIT(list, "","")), names, XLOOKUP( arr, 'Conformance Score'!A:A, 'Conformance Score'!B:B, ""Not found"" "&" ), TEXTJOIN("", "", TRUE, names) ), """" ) ), 1, 1 ) "),"") | P18: =IF(F18="Yes", IFERROR(VLOOKUP(D18, Repository!A:F, 6, 0), ""), "") | Q18: =IF(F18="Yes", IFERROR(VLOOKUP(D18, Repository!A:I, 8, 0), ""), "") | R18: =IF(F18="Yes", IFERROR(VLOOKUP(D18, Repository!A:J, 9, 0), ""), "") | AI18: =IF(L18="","", IF(L18="Blocker",1, IF(L18="Critical",2, IF(L18="Major",3, IF(L18="Minor",4,""))))) | AJ18: =IF(P18="","", IF(P18="A",1, IF(P18="AA",2, IF(P18="AAA",3,""))))
B19: =IFERROR(__xludf.DUMMYFUNCTION("ARRAY_CONSTRAIN( ARRAYFORMULA( IF( 'Final Report'!A19="""", """", TEXTJOIN( "", "" & CHAR(10), TRUE, IFERROR( VLOOKUP( TRIM( SPLIT('Final Report'!A19, "","") )"&", 'URL Details'!A:B, 2, FALSE ), """" ) ) ) ), 1, 1 ) "),"") | C19: =IFERROR(__xludf.DUMMYFUNCTION("IFERROR(IF('Final Report'!A19="""","""", TEXTJOIN(CHAR(10), TRUE, ARRAYFORMULA( ""• ""& FILTER( TRIM(FLATTEN(SPLIT( REGEXREPLACE( SUBSTITUTE(TEXTJOIN("","", TRUE, IFERROR(ARRAYFORMULA(VLOOKUP(TRIM(SPLIT('Final Report'!A19, "","")), 'URL Details'!A:D, 4, F"&"ALSE)),"""") ), CHAR(10), "",""), ""\s*,\s*"", "",""), "",""))), TRIM(FLATTEN(SPLIT( REGEXREPLACE( SUBSTITUTE(TEXTJOIN("","", TRUE, IFERROR(ARRAYFORMULA(VLOOKUP(TRIM(SPLIT('Final Report'!A19, "","")), 'URL Details'!A:D, 4, FALSE)),"""") ), CHAR(10), "","""&"), ""\s*,\s*"", "",""), "","")))<>"""" ) ) ) ),"""") "),"") | F19: FALSE | G19: =IF(F19=True, IFERROR(VLOOKUP(D19, Repository!A:B, 2, 0), ""), "") | J19: =IF(F19=True, IFERROR(VLOOKUP(D19, Repository!A:C, 3, 0), ""), "") | L19: =IF(F19=True, IFERROR(VLOOKUP(D19, Repository!A:E, 5, 0), ""), "") | N19: =IF(F19=True, IFERROR(VLOOKUP(D19, Repository!A:G, 7, 0), ""), "") | O19: =IFERROR(__xludf.DUMMYFUNCTION("ARRAY_CONSTRAIN( ARRAYFORMULA( IFERROR( LET( list, N19, arr, TRIM(SPLIT(list, "","")), names, XLOOKUP( arr, 'Conformance Score'!A:A, 'Conformance Score'!B:B, ""Not found"" "&" ), TEXTJOIN("", "", TRUE, names) ), """" ) ), 1, 1 ) "),"") | P19: =IF(F19="Yes", IFERROR(VLOOKUP(D19, Repository!A:F, 6, 0), ""), "") | Q19: =IF(F19="Yes", IFERROR(VLOOKUP(D19, Repository!A:I, 8, 0), ""), "") | R19: =IF(F19="Yes", IFERROR(VLOOKUP(D19, Repository!A:J, 9, 0), ""), "") | AI19: =IF(L19="","", IF(L19="Blocker",1, IF(L19="Critical",2, IF(L19="Major",3, IF(L19="Minor",4,""))))) | AJ19: =IF(P19="","", IF(P19="A",1, IF(P19="AA",2, IF(P19="AAA",3,""))))
B20: =IFERROR(__xludf.DUMMYFUNCTION("ARRAY_CONSTRAIN( ARRAYFORMULA( IF( 'Final Report'!A20="""", """", TEXTJOIN( "", "" & CHAR(10), TRUE, IFERROR( VLOOKUP( TRIM( SPLIT('Final Report'!A20, "","") )"&", 'URL Details'!A:B, 2, FALSE ), """" ) ) ) ), 1, 1 ) "),"") | C20: =IFERROR(__xludf.DUMMYFUNCTION("IFERROR(IF('Final Report'!A20="""","""", TEXTJOIN(CHAR(10), TRUE, ARRAYFORMULA( ""• ""& FILTER( TRIM(FLATTEN(SPLIT( REGEXREPLACE( SUBSTITUTE(TEXTJOIN("","", TRUE, IFERROR(ARRAYFORMULA(VLOOKUP(TRIM(SPLIT('Final Report'!A20, "","")), 'URL Details'!A:D, 4, F"&"ALSE)),"""") ), CHAR(10), "",""), ""\s*,\s*"", "",""), "",""))), TRIM(FLATTEN(SPLIT( REGEXREPLACE( SUBSTITUTE(TEXTJOIN("","", TRUE, IFERROR(ARRAYFORMULA(VLOOKUP(TRIM(SPLIT('Final Report'!A20, "","")), 'URL Details'!A:D, 4, FALSE)),"""") ), CHAR(10), "","""&"), ""\s*,\s*"", "",""), "","")))<>"""" ) ) ) ),"""") "),"") | F20: FALSE | G20: =IF(F20=True, IFERROR(VLOOKUP(D20, Repository!A:B, 2, 0), ""), "") | J20: =IF(F20=True, IFERROR(VLOOKUP(D20, Repository!A:C, 3, 0), ""), "") | L20: =IF(F20=True, IFERROR(VLOOKUP(D20, Repository!A:E, 5, 0), ""), "") | N20: =IF(F20=True, IFERROR(VLOOKUP(D20, Repository!A:G, 7, 0), ""), "") | O20: =IFERROR(__xludf.DUMMYFUNCTION("ARRAY_CONSTRAIN( ARRAYFORMULA( IFERROR( LET( list, N20, arr, TRIM(SPLIT(list, "","")), names, XLOOKUP( arr, 'Conformance Score'!A:A, 'Conformance Score'!B:B, ""Not found"" "&" ), TEXTJOIN("", "", TRUE, names) ), """" ) ), 1, 1 ) "),"") | P20: =IF(F20="Yes", IFERROR(VLOOKUP(D20, Repository!A:F, 6, 0), ""), "") | Q20: =IF(F20="Yes", IFERROR(VLOOKUP(D20, Repository!A:I, 8, 0), ""), "") | R20: =IF(F20="Yes", IFERROR(VLOOKUP(D20, Repository!A:J, 9, 0), ""), "") | AI20: =IF(L20="","", IF(L20="Blocker",1, IF(L20="Critical",2, IF(L20="Major",3, IF(L20="Minor",4,""))))) | AJ20: =IF(P20="","", IF(P20="A",1, IF(P20="AA",2, IF(P20="AAA",3,""))))
B21: =IFERROR(__xludf.DUMMYFUNCTION("ARRAY_CONSTRAIN( ARRAYFORMULA( IF( 'Final Report'!A21="""", """", TEXTJOIN( "", "" & CHAR(10), TRUE, IFERROR( VLOOKUP( TRIM( SPLIT('Final Report'!A21, "","") )"&", 'URL Details'!A:B, 2, FALSE ), """" ) ) ) ), 1, 1 ) "),"") | C21: =IFERROR(__xludf.DUMMYFUNCTION("IFERROR(IF('Final Report'!A21="""","""", TEXTJOIN(CHAR(10), TRUE, ARRAYFORMULA( ""• ""& FILTER( TRIM(FLATTEN(SPLIT( REGEXREPLACE( SUBSTITUTE(TEXTJOIN("","", TRUE, IFERROR(ARRAYFORMULA(VLOOKUP(TRIM(SPLIT('Final Report'!A21, "","")), 'URL Details'!A:D, 4, F"&"ALSE)),"""") ), CHAR(10), "",""), ""\s*,\s*"", "",""), "",""))), TRIM(FLATTEN(SPLIT( REGEXREPLACE( SUBSTITUTE(TEXTJOIN("","", TRUE, IFERROR(ARRAYFORMULA(VLOOKUP(TRIM(SPLIT('Final Report'!A21, "","")), 'URL Details'!A:D, 4, FALSE)),"""") ), CHAR(10), "","""&"), ""\s*,\s*"", "",""), "","")))<>"""" ) ) ) ),"""") "),"") | F21: FALSE | G21: =IF(F21=True, IFERROR(VLOOKUP(D21, Repository!A:B, 2, 0), ""), "") | J21: =IF(F21=True, IFERROR(VLOOKUP(D21, Repository!A:C, 3, 0), ""), "") | L21: =IF(F21=True, IFERROR(VLOOKUP(D21, Repository!A:E, 5, 0), ""), "") | N21: =IF(F21=True, IFERROR(VLOOKUP(D21, Repository!A:G, 7, 0), ""), "") | O21: =IFERROR(__xludf.DUMMYFUNCTION("ARRAY_CONSTRAIN( ARRAYFORMULA( IFERROR( LET( list, N21, arr, TRIM(SPLIT(list, "","")), names, XLOOKUP( arr, 'Conformance Score'!A:A, 'Conformance Score'!B:B, ""Not found"" "&" ), TEXTJOIN("", "", TRUE, names) ), """" ) ), 1, 1 ) "),"") | P21: =IF(F21="Yes", IFERROR(VLOOKUP(D21, Repository!A:F, 6, 0), ""), "") | Q21: =IF(F21="Yes", IFERROR(VLOOKUP(D21, Repository!A:I, 8, 0), ""), "") | R21: =IF(F21="Yes", IFERROR(VLOOKUP(D21, Repository!A:J, 9, 0), ""), "") | AI21: =IF(L21="","", IF(L21="Blocker",1, IF(L21="Critical",2, IF(L21="Major",3, IF(L21="Minor",4,""))))) | AJ21: =IF(P21="","", IF(P21="A",1, IF(P21="AA",2, IF(P21="AAA",3,""))))
B22: =IFERROR(__xludf.DUMMYFUNCTION("ARRAY_CONSTRAIN( ARRAYFORMULA( IF( 'Final Report'!A22="""", """", TEXTJOIN( "", "" & CHAR(10), TRUE, IFERROR( VLOOKUP( TRIM( SPLIT('Final Report'!A22, "","") )"&", 'URL Details'!A:B, 2, FALSE ), """" ) ) ) ), 1, 1 ) "),"") | C22: =IFERROR(__xludf.DUMMYFUNCTION("IFERROR(IF('Final Report'!A22="""","""", TEXTJOIN(CHAR(10), TRUE, ARRAYFORMULA( ""• ""& FILTER( TRIM(FLATTEN(SPLIT( REGEXREPLACE( SUBSTITUTE(TEXTJOIN("","", TRUE, IFERROR(ARRAYFORMULA(VLOOKUP(TRIM(SPLIT('Final Report'!A22, "","")), 'URL Details'!A:D, 4, F"&"ALSE)),"""") ), CHAR(10), "",""), ""\s*,\s*"", "",""), "",""))), TRIM(FLATTEN(SPLIT( REGEXREPLACE( SUBSTITUTE(TEXTJOIN("","", TRUE, IFERROR(ARRAYFORMULA(VLOOKUP(TRIM(SPLIT('Final Report'!A22, "","")), 'URL Details'!A:D, 4, FALSE)),"""") ), CHAR(10), "","""&"), ""\s*,\s*"", "",""), "","")))<>"""" ) ) ) ),"""") "),"") | F22: FALSE | G22: =IF(F22=True, IFERROR(VLOOKUP(D22, Repository!A:B, 2, 0), ""), "") | J22: =IF(F22=True, IFERROR(VLOOKUP(D22, Repository!A:C, 3, 0), ""), "") | L22: =IF(F22=True, IFERROR(VLOOKUP(D22, Repository!A:E, 5, 0), ""), "") | N22: =IF(F22=True, IFERROR(VLOOKUP(D22, Repository!A:G, 7, 0), ""), "") | O22: =IFERROR(__xludf.DUMMYFUNCTION("ARRAY_CONSTRAIN( ARRAYFORMULA( IFERROR( LET( list, N22, arr, TRIM(SPLIT(list, "","")), names, XLOOKUP( arr, 'Conformance Score'!A:A, 'Conformance Score'!B:B, ""Not found"" "&" ), TEXTJOIN("", "", TRUE, names) ), """" ) ), 1, 1 ) "),"") | P22: =IF(F22="Yes", IFERROR(VLOOKUP(D22, Repository!A:F, 6, 0), ""), "") | Q22: =IF(F22="Yes", IFERROR(VLOOKUP(D22, Repository!A:I, 8, 0), ""), "") | R22: =IF(F22="Yes", IFERROR(VLOOKUP(D22, Repository!A:J, 9, 0), ""), "") | AI22: =IF(L22="","", IF(L22="Blocker",1, IF(L22="Critical",2, IF(L22="Major",3, IF(L22="Minor",4,""))))) | AJ22: =IF(P22="","", IF(P22="A",1, IF(P22="AA",2, IF(P22="AAA",3,""))))
B23: =IFERROR(__xludf.DUMMYFUNCTION("ARRAY_CONSTRAIN( ARRAYFORMULA( IF( 'Final Report'!A23="""", """", TEXTJOIN( "", "" & CHAR(10), TRUE, IFERROR( VLOOKUP( TRIM( SPLIT('Final Report'!A23, "","") )"&", 'URL Details'!A:B, 2, FALSE ), """" ) ) ) ), 1, 1 ) "),"") | C23: =IFERROR(__xludf.DUMMYFUNCTION("IFERROR(IF('Final Report'!A23="""","""", TEXTJOIN(CHAR(10), TRUE, ARRAYFORMULA( ""• ""& FILTER( TRIM(FLATTEN(SPLIT( REGEXREPLACE( SUBSTITUTE(TEXTJOIN("","", TRUE, IFERROR(ARRAYFORMULA(VLOOKUP(TRIM(SPLIT('Final Report'!A23, "","")), 'URL Details'!A:D, 4, F"&"ALSE)),"""") ), CHAR(10), "",""), ""\s*,\s*"", "",""), "",""))), TRIM(FLATTEN(SPLIT( REGEXREPLACE( SUBSTITUTE(TEXTJOIN("","", TRUE, IFERROR(ARRAYFORMULA(VLOOKUP(TRIM(SPLIT('Final Report'!A23, "","")), 'URL Details'!A:D, 4, FALSE)),"""") ), CHAR(10), "","""&"), ""\s*,\s*"", "",""), "","")))<>"""" ) ) ) ),"""") "),"") | F23: FALSE | G23: =IF(F23=True, IFERROR(VLOOKUP(D23, Repository!A:B, 2, 0), ""), "") | J23: =IF(F23=True, IFERROR(VLOOKUP(D23, Repository!A:C, 3, 0), ""), "") | L23: =IF(F23=True, IFERROR(VLOOKUP(D23, Repository!A:E, 5, 0), ""), "") | N23: =IF(F23=True, IFERROR(VLOOKUP(D23, Repository!A:G, 7, 0), ""), "") | O23: =IFERROR(__xludf.DUMMYFUNCTION("ARRAY_CONSTRAIN( ARRAYFORMULA( IFERROR( LET( list, N23, arr, TRIM(SPLIT(list, "","")), names, XLOOKUP( arr, 'Conformance Score'!A:A, 'Conformance Score'!B:B, ""Not found"" "&" ), TEXTJOIN("", "", TRUE, names) ), """" ) ), 1, 1 ) "),"") | P23: =IF(F23="Yes", IFERROR(VLOOKUP(D23, Repository!A:F, 6, 0), ""), "") | Q23: =IF(F23="Yes", IFERROR(VLOOKUP(D23, Repository!A:I, 8, 0), ""), "") | R23: =IF(F23="Yes", IFERROR(VLOOKUP(D23, Repository!A:J, 9, 0), ""), "") | AI23: =IF(L23="","", IF(L23="Blocker",1, IF(L23="Critical",2, IF(L23="Major",3, IF(L23="Minor",4,""))))) | AJ23: =IF(P23="","", IF(P23="A",1, IF(P23="AA",2, IF(P23="AAA",3,""))))
